Workbook

Sheet Required Info
A1: Silver Sycamore - Intimate Wedding Details Planner
A4: Date(s) Booked: | C4: Bride: | E4: Groom:
A5: Person Completing Form: | B5: (List your name here please) | C5: Your Role in Big Day: | D5: (Bride? Groom? MOH? MOB?) | E5: Main Contact Name/Number:
A7: How To Use This Document:
A8: We're so excited to host your big day at Silver Sycamore! This document has been put together to help you in the planning process and is designed for use on a desktop computer. You can add/edit/change up until the deadline stated below. If you know at any time everything on the first tab in PINK is FINAL, mark an X in the GREEN box below. The cells in PINK below are REQUIRED for us to prepare for your big day. The Cells in PURPLE AND PINK are for those who are Renting Venue only and must complete .The cells in blue are helpful to us, but optional. The tabs following the "REQUIRED INFORMATION" tab are not necessary to be completed, but we believe may be helpful to you in the planning process. The cells in yellow are set by the venue and MAY NOT be edited. If you see an error in a yellow cell please contact us ASAP. Please note we will have shared access to this document with you. We can "see" the updates you make without you having to submit the document to us. Also, please note, to change the content in a cell you have already written in, double click the cell before you start editing. (If you don't you'll delete the contents of the cell and start over.) Also, please note that this is a FREE tool provided by Silver Sycamore. We have done our best to ensure that there are no mistakes or errors in formulas, calculations, etc. Please do your own due diligence to ensure accuracy and let us know if you see any errors. We hope you find this document helpful in the planning process!
A11: Please Complete the Following by ------------>
A12: Mark an "X" here when final --->
A15: Timing of Events: | B15: (Time Below for Coordinated All Inclusive Event | C15: (List Time Below For Venue Rental only)
A16: Silver Sycamore Opens
A17: Arrival at Bridal Cottage
A18: Arrival at Jail
A19: Decorating Begins
A20: First Look Photos of Couple
A21: Ceremony Begins
A22: Bar Opens
A23: Bridal Party Announced/Formal Photos in Chapel
A24: Dinner Serivce
A25: Cake Cutting
A26: Toasts
A27: First Dance/Special Dances
... A32: Silver Sycamore Gates Close
A34: Contact Information | B34: Name | C34: Phone | D34: Is Text Okay? Yes/No
A35: Decision Maker for Day | G35: (Should NOT be bride/groom/members of bridal party)
B37: Name | C37: Business Name | D37: Email Address | E37: Arrival Time at Venue | F37: Cell Phone in Case of Emergency | G37: (Website) | H37: Professional Vendor/Friend/Family?
A38: Officiant
A39: Photographer
A40: DJ / Band (if applicable)
A41: Videographer
A42: Bar Service | C42: SILVER SYCAMORE
A43: Wedding Day Caterer if not SS
A44: Rehearsal Dinner location (if rented Silver Sycamore for Rehearsal Dinner)
A45: Florist
A46: Photo Booth
A47: Cake/Sweets
A48: Dress Shop
A49: Suit Shop
A50: Stationery/Paper Goods
A51: Other Vendor
A52: Hair/Makeup
A53: Coordinator -if not Silver Sycamore provided in package
...

Sheet Printable
A1: Wedding Date: | B1: ='Required Info'!B4
A2: Bride: | B2: ='Required Info'!D4
A3: Groom: | B3: ='Required Info'!F4 | D3: ='Required Info'!A126
A4: Ceremony Begins | B4: ='Required Info'!B21
A5: Music Concludes/ Event Ends | B5: ='Required Info'!B31
A6: Decision Maker for Day | B6: ='Required Info'!B35:F35
A7: Desiin maker phone number | B7: ='Required Info'!C35
A9: Officiant | B9: ='Required Info'!B38 | C9: ='Required Info'!F38
A10: Photographer | B10: ='Required Info'!B39 | C10: ='Required Info'!F39
A11: DJ / Band if not SS | B11: ='Required Info'!B40 | C11: ='Required Info'!F40
A12: Videographer | B12: ='Required Info'!B41 | C12: ='Required Info'!F41
A13: Wedding Day Caterer if not SS | B13: ='Required Info'!B43 | C13: ='Required Info'!F43
A14: Florist | B14: ='Required Info'!B45 | C14: ='Required Info'!F45
A15: Photo Booth | B15: ='Required Info'!B46 | C15: ='Required Info'!F46
A16: Cake/Sweets | B16: ='Required Info'!B47 | C16: ='Required Info'!F47
A18: Ceremony Location | B18: ='Required Info'!B57
A19: Will you be having a Sand Ceremony and need a table? | B19: ='Required Info'!B62
A21: Reception Location | B21: ='Required Info'!B74
A22: Would you prefer food service outside or in Saloon if have a Town Reception? | B22: ='Required Info'!B77
A23: Any extra tables needed? if so , which size and where do you need them? | B23: ='Required Info'!B87
A24: How many tables for the bridal party to be reserved? | B24: ='Required Info'!B84
A25: How many tables Reserved for the Family? | B25: ='Required Info'!B85
A26: What size dance floor are you using outside? | B26: ='Required Info'!B89
A27: Will you have alcohol? | B27: ='Required Info'!B100
A28: What will your exit be with? | B28: ='Required Info'!B108
A30: Any extra Rental Items like Heater/Coolers or amusements | B30: ='Required Info'!B95

Sheet Street of Town Layout
A1: Date: | B1: ='Required Info'!B4 | C1: Bride: | D1: ='Required Info'!D4 | E1: Groom: | F1: ='Required Info'!F4
A3: Venue Layout
A4: **DO NOT DELETE TABLES - DRAG THEM OFF THE LAYOUT IF YOU DON'T NEED THEM
M7: **DO NOT CHANGE THE SIZE OF ANY OF THE TABLES BELOW. THEY ARE ROUGHLY TO SCALE.
M10: 20 IS THE MAX NUMBER OF TABLES WITH A DANCE FLOOR

Sheet Saloon Layout
A1: Date | C1: Bride | E1: Groom
A3: Saloon Layout
A4: **Do not delete tables. Drag them off the layout if you do not need them**

Sheet Questions Post Them Here
A2: Haue Valley - Q&A Chat
A5: **Do you have questions for the Haue Valley team that you normally would send via email? Instead, ask the question below AND then right click on the cell, select "insert comment" and comment @hauevalley@gmail.com (write that exactly and we will be notified that you have a question). We will respond in the box below and you will be notified via email. This is a great way to keep all of our communication in one place, as opposed to spread out over multiple emails. YOU MUST RIGHT CLICK AND INSERT A COMMENT USING THE @HAUEVALLEY@GMAIL.COM EVERY TIME YOU TYPE A NEW QUESTION IN ORDER TO NOTIFY US THAT YOU HAVE ONE. THANKS!!
A8: =HYPERLINK("http://hauevalleyweddings.com/faqs/","Answers to many FAQs can be found here: http://hauevalleyweddings.com/faqs/") -> Answers to many FAQs can be found here: http://hauevalleyweddings.com/faqs/
A10: Question:
A11: Answer:
A13: Question:
A14: Answer:
A16: Question:
A17: Answer:
A19: Question:
A20: Answer:
A22: Question:
A23: Answer:
A25: Question:
A26: Answer:
... A65: Answer:

Sheet Blog Feature Information
A2: Silver Sycamore Blog Feature
A4: How to use this tab:
A5: Greetings! We would LOVE to feature your big day on social media, on the blog, etc. Below are details we would like to know to help tell the story of your wedding day. Please note we do need YOU to please send us your professional photos in order to be featured and we need written permission from your photographer to post them.
A9: Would you like your wedding to be featured on our blog?
A10: Tell us the short story of how you met one another.
A11: Tell us about the proposal!
A12: What moment are you most looking forward to on your wedding day? (Make sure your photographer knows to capture it!)
A13: Why did you choose Silver Sycamore?
A14: In a few words describe your theme or style for your wedding. (Ie- Boho, Glam, Rustic, Etc.)
A15: Is there anything else you can tell us about your love story?
A16: Is there anything else you think future couples will find interesting / helpful about your wedding? (Ie - planned from out of state, a must have was your dog in the ceremony, etc.)
A17: Do you have any advice for future couples?
... A19: Will you remember to send us your professional photos when you receive them?

Sheet Wedding Day Schedule
A2: Wedding Day Schedule
A4: How to use this tab: | C4: This is YOUR Schedule !
A5: This tab is completely customizable with the exception of the rows in yellow. Feel free to modify to fit your schedule.
B8: Time: | C8: Location: | D8: Point Person: | E8: Point Person Number: | F8: Important Notes:
A9: Bridesmaids Meet Bride
A10: Groomsmen Meet Groom
A11: Breakfast/Snacks Delivered to Ladies & Men
A12: Hair and Makeup Begins
A13: Hair and Makeup Completed | F13: < Insert helpful notes>
A14: Before Ceremony Pics
A15: Venue Opens | B15: ='Required Info'!B16 | F15: *Please make sure your outside vendors are aware of this time
A16: Decorating Begins | F16: *Generally as soon as venue opens
A17: Lunch/Snacks Delivered to Venue by Someone
A18: Photographer Arrives | F18: *Confirm time week of wedding
A19: Videographer Arrives | F19: *Confirm time week of wedding
A20: Florist Arrives | F20: *Confirm time week of wedding
A21: Cake/Treats Arrives | F21: *Confirm time week of wedding
A22: Men Arrive at Venue and get Dressed
A23: Put on The Dress
A24: First Look Photos With Bride/Groom
A25: First Look Photos With Bride & Other Special People
A26: Bartenders Arrive | F26: *Confirm time week of wedding
A27: Bridal Party Lines Up
A28: Ceremony Begins | F28: *Generally plan for 30 minutes / Reminder no birdseed or confetti, faux flower petals thrown, etc.
A29: Ceremony Ends
A30: Bar Opens | F30: *Generally immediately after the ceremony
A31: Family, Bridal Party, and Couples Photos | F31: *Generally plan for30-50 minutes
A32: Bridal Party Announced
A33: Buffe Opens
A34: Cake Cutting | F34: *Confirm who is cutting and serving your cake. Reminder cake plate/napkins/silverware is not included by caterers.
A35: Toast
A36: First Dance
A37: Pack Gifts into Vehicle
A38: Bar Closes
A39: Venue Closes | B39: ='Required Info'!B32 | F39: *Please make sure your outside vendors are aware of this time
A40: Party continued off site | F40: < enter site>

Sheet Packing List
A2: Wedding Day Packing List
A4: How to use this tab:
A5: This tab can be completely customizable with the exception of the rows in yellow. Feel free to modify to fit your needs.
A9: Item | B9: Who's Responsible | C9: Picked Up From (Location) | D9: Delivered To (Location) | E9: Delivered By (Time) | F9: What Happens to This Item at the End of the Night?
A10: Copy of save the date, wedding invitation, etc. for your photographer to take pictures of
A11: Marriage license
A12: Rings
A13: Shoes
A14: Dress
A15: Tuxedo

Sheet To Do List
A2: To Do List
A3: *This is just a starting point! Add lines and make it your own.
A6: Task | B6: Due | C6: Status | D6: Person Responsible | E6: Notes:
A7: Print & save a copy of Silver Sycamore contract
A8: Book Silver Sycamore Bed and Breakfast room block | G8: Looking for recommendations on vendors?
A9: Book photographer | E9: (Generally photographers book one couple per day. Book yours as soon as you have a date.) | G9: < Enter Link>
A10: Schedule engagement photos | E10: (These can be taken on Silver Sycamore grounds just call for appointment time)
A11: Purchase wedding attire | E11: (Dresses take much longer to order than many brides expect!)
A12: Send save the dates (optional)
A13: Touch base with DJ/band (optional) | E13: (DJ's do SO MUCH more than just play music. They play a critical role in the success of your day.)
A14: Book videographer | E14: (Some book as far in advance as photographers.)
A15: Book florist | E15: (Some book as far in advance as photographers.)
A16: Attend a Silver Sycamore open house | E16: Check our Calendar for dates
A17: Book Rehearsal Dinner | E17: Check pricing at Silver Sycamore
A18: Book officiant | E18: (Make sure they are reliable! They are critical to your big day.)
A19: Schedule catering tastings
A20: Schedule cake tasting /sweets
A21: Determine shower date(s) | E21: (Check dates and Shower Pricing at Silver Sycamore)
A22: Send shower thank you cards
A23: Finalize guest list
A24: Send invitations
A25: Get marriage license
A26: Complete required information tab | B26: ='Required Info'!C11
A27: Confirm timeline with all vendors / family / bridal party
A28: Finalize seating chart (optional)
A29: Rehearsal
A30: Send thank you cards

Sheet Guest List
A2: Invitation Tracker
A3: *Guests often return RSVP cards without a name on accident. Consider marking each RSVP card with a number so you know who has returned them and who hasn't!
A5: Invitation # | B5: Guest Name | C5: # Invited | D5: Mailed? | E5: RSVP | F5: # Accepted | G5: Bride or Groom's Side | H5: Address | I5: City | J5: State | K5: Zip | L5: Phone | M5: Email | N5: Shower Invite? | O5: # Attending Shower | P5: Shower Thank You Sent? | Q5: Wedding Thank You Sent
A6: 1 | B6: The Family of Tom Jones | C6: 4 | D6: Yes | E6: Attending | F6: 3 | G6: Bride | H6: 123 Tom Street | I6: Houston | J6: TX | K6: 77508 | L6: 111.111.1111 | M6: Example@example.com | N6: Yes | O6: 0 | P6: Yes | Q6: Yes
B21: Total: | C21: =sum(C6:C20) -> 4 | F21: =sum(F6:F20) -> 3 | O21: =sum(O6:O20) -> 0

Sheet Table Assigments
A2: Table Assignments
A3: Note: At Silver Sycamore we generally do not recommend assigned seating unless you believe you will max out capacity at 200 guests. You have several options for seating at our venue. 1) All open seating 2) A few reserved tables for close family or 3) An assigned seat for each guest. It's completely up to you! By entering each name into a cell below your total number of head table party members and total guests not sitting at the head table will total for you. These numbers should match your confirmed guest RSVPs once you have assigned each person a seat.
A7: Total Head Table: | B7: =COUNTA(A10:A30) -> 4 | C7: Total Guest Seats Assigned: | E7: =sum(B26:Z26) -> 3
A9: Head Table | B9: Table 1 | C9: Table 2 | D9: Table 3 | E9: Table 4 | F9: Table 5 | G9: Table 6 | H9: Table 7 | I9: Table 8 | J9: Table 9 | K9: Table 10 | L9: Table 11 | M9: Table 12 | N9: Table 13 | O9: Table 14 | P9: Table 15 | Q9: Table 16 | R9: Table 17 | S9: Table 18 | T9: Table 19 | U9: Table 20 | V9: Table 21 | W9: Table 22 | X9: Table 23 | Y9: Table 24 | Z9: Table 25
A10: Bride Name | B10: Guest 1 Name
A11: Groom Name | B11: Guest 2 Name
A12: MOH Name | B12: etc.
A13: Etc.
B26: =8-Countblank(B10:B17) -> 3 | C26: =8-Countblank(C10:C17) -> 0 | D26: =8-Countblank(D10:D17) -> 0 | E26: =8-Countblank(E10:E17) -> 0 | F26: =8-Countblank(F10:F17) -> 0 | G26: =8-Countblank(G10:G17) -> 0 | H26: =8-Countblank(H10:H17) -> 0 | I26: =8-Countblank(I10:I17) -> 0 | ... Z26: =8-Countblank(Z10:Z17) -> 0

Sheet Song Idea List
